<?xml version='1.0'?>
<sdf version='1.6'>
  
  <model name='s500'>


    <!--Links-->
    <link name='drone_frame'>
      <pose frame=''>0 0 0.170 0 0 0</pose>
      <inertial>
        <pose>0 0 0 0 -0 0</pose>
        <mass>0.935</mass>
        <inertia>
          <ixx>0.01570261</ixx>
          <ixy>0.00000158</ixy>
          <ixz>-0.00000005</ixz>
          <iyy>0.01998355</iyy>
          <iyz>0.00004291</iyz>
          <izz>0.01648553</izz>
        </inertia>        
      </inertial>
      <collision name='collision_drone_frame'>
        <pose>0 0 0 0 -0 0</pose>
        <geometry>
          <mesh>
            <uri>model://s500/meshes/s500_for_livox.STL</uri>
            <scale>0.001 0.001 0.001</scale>
          </mesh>
        </geometry>
        <surface>
          <contact>
            <ode>
              <min_depth>0.001</min_depth>
              <max_vel>0</max_vel>
            </ode>
          </contact>
          <friction>
            <ode/>
          </friction>
        </surface>
      </collision>
      <visual name='visual_drone_frame'>
        <pose>0 0 0 0 -0 0</pose>
        <geometry>
          <mesh>
            <uri>model://s500/meshes/s500_for_livox.STL</uri>
            <scale>0.001 0.001 0.001</scale>
          </mesh>
        </geometry>
        <material>
          <script>
            <name>Gazebo/Grey</name>
            <uri>__default__</uri>
          </script>
        </material>      
      </visual>
      <gravity>1</gravity>
      <velocity_decay/>
      <self_collide>0</self_collide>
    </link>


    <link name='livox_lipo_ass'>
      <pose>0 0 0.1325 0 0 0</pose>
      <inertial>
        <mass>0.200</mass>
        <inertia>
          <ixx>0.00391525</ixx>
          <ixy>0.00000001</ixy>
          <ixz>0.00000000</ixz>
          <iyy>0.00459083</iyy>
          <iyz>-0.00024462</iyz>
          <izz>0.00142686</izz>
        </inertia>        
      </inertial>
      <visual name='visual_livox_lipo_ass'>   
        <pose>0 0 0 0 -0 0</pose> 
        <geometry>
          <mesh>
            <uri>model://s500/meshes/livox_lipo_ass.STL</uri>
            <scale>0.001 0.001 0.001</scale>
          </mesh>
        </geometry>
        <material>
          <script>
            <name>Gazebo/White</name>
            <uri>__default__</uri>
          </script>
        </material>
      </visual>
      <gravity>1</gravity>
      <velocity_decay/>
      <self_collide>0</self_collide>
      <sensor type="ray" name="livox">
        <!--topic>s500/lidar</topic-->
        <pose>0.094 0 0.013 3.141593 0 0</pose>
        <visualize>True</visualize>
        <update_rate>100000.0</update_rate> <!-- Change value -->
        <ray>
          <scan>
            <horizontal>
              <samples>50</samples> <!-- Change value -->
              <resolution>1</resolution>
              <min_angle>-0.61435590</min_angle>
              <max_angle>0.61435590</max_angle>
            </horizontal>
            <vertical>
              <samples>50</samples> <!-- Change value -->
              <resolution>1</resolution>
              <min_angle>-0.61435590</min_angle>
              <max_angle>0.61435590</max_angle>
            </vertical>
          </scan>
          <range>
            <min>0.05</min>
            <max>130</max>
            <!--resolution>0.02</resolution-->
          </range>
        </ray>
      </sensor>
    </link>


    <link name='prop_1'>
      <pose>0.169 -0.169 0.273 0 -0 0</pose> 
      <inertial>
        <mass>0.005</mass>
        <inertia>
          <ixx>0.00008835</ixx>
          <ixy>0</ixy>
          <ixz>-0.00001282</ixz>
          <iyy>0.00009080</iyy>
          <iyz>0</iyz>
          <izz>0.00000260</izz>
        </inertia>
      </inertial>
      <collision name='collision_prop_1'> 
        <pose>0 0 0 0 -0 0</pose>  
        <geometry>
          <cylinder>
            <length>0.01</length>
            <radius>0.128</radius>
          </cylinder>
        </geometry>
        <surface>
          <contact>
            <ode/>
          </contact>
          <friction>
            <ode/>
          </friction>
        </surface>
      </collision>   
      <visual name='visual_prop_1'> 
        <pose>0 0 0 0 -0 0</pose>
        <geometry>
          <mesh>
            <uri>model://s500/meshes/10in_prop.STL</uri>
            <scale>0.001 0.001 0.001</scale>
          </mesh>
        </geometry>
        <material>
          <script>
            <name>Gazebo/Blue</name>
            <uri>__default__</uri>
          </script>
        </material>
      </visual>
      <gravity>1</gravity> 
      <velocity_decay/>
      <self_collide>0</self_collide>      
    </link>


    <link name='prop_2'>
      <pose>-0.169 0.169 0.273 0 -0 0</pose> 
      <inertial>
        <mass>0.005</mass>
        <inertia>
          <ixx>0.00008835</ixx>
          <ixy>0</ixy>
          <ixz>-0.00001282</ixz>
          <iyy>0.00009080</iyy>
          <iyz>0</iyz>
          <izz>0.00000260</izz>
        </inertia>
      </inertial>
      <collision name='collision_prop_2'> 
        <pose>0 0 0 0 -0 0</pose>  
        <geometry>
          <cylinder>
            <length>0.01</length>
            <radius>0.128</radius>
          </cylinder>
        </geometry>
        <surface>
          <contact>
            <ode/>
          </contact>
          <friction>
            <ode/>
          </friction>
        </surface>
      </collision>   
      <visual name='visual_prop_2'> 
        <pose>0 0 0 0 -0 0</pose>
        <geometry>
          <mesh>
            <uri>model://s500/meshes/10in_prop.STL</uri>
            <scale>0.001 0.001 0.001</scale>
          </mesh>
        </geometry>
        <material>
          <script>
            <name>Gazebo/DarkGrey</name>
            <uri>__default__</uri>
          </script>
        </material>
      </visual>
      <gravity>1</gravity> 
      <velocity_decay/>
      <self_collide>0</self_collide>      
    </link>


    <link name='prop_3'>
      <pose>0.169 0.169 0.273 0 -0 0</pose> 
      <inertial>
        <mass>0.005</mass>
        <inertia>
          <ixx>0.00008835</ixx>
          <ixy>0</ixy>
          <ixz>-0.00001282</ixz>
          <iyy>0.00009080</iyy>
          <iyz>0</iyz>
          <izz>0.00000260</izz>
        </inertia>
      </inertial>
      <collision name='collision_prop_3'> 
        <pose>0 0 0 0 -0 0</pose>  
        <geometry>
          <cylinder>
            <length>0.01</length>
            <radius>0.128</radius>
          </cylinder>
        </geometry>
        <surface>
          <contact>
            <ode/>
          </contact>
          <friction>
            <ode/>
          </friction>
        </surface>
      </collision>   
      <visual name='visual_prop_3'> 
        <pose>0 0 0 0 -0 0</pose>
        <geometry>
          <mesh>
            <uri>model://s500/meshes/10in_prop.STL</uri>
            <scale>0.001 0.001 0.001</scale>
          </mesh>
        </geometry>
        <material>
          <script>
            <name>Gazebo/Blue</name>
            <uri>__default__</uri>
          </script>
        </material>
      </visual>
      <gravity>1</gravity> 
      <velocity_decay/>
      <self_collide>0</self_collide>      
    </link>


    <link name='prop_4'>
      <pose>-0.169 -0.169 0.273 0 -0 0</pose> 
      <inertial>
        <mass>0.005</mass>
        <inertia>
          <ixx>0.00008835</ixx>
          <ixy>0</ixy>
          <ixz>-0.00001282</ixz>
          <iyy>0.00009080</iyy>
          <iyz>0</iyz>
          <izz>0.00000260</izz>
        </inertia>
      </inertial>
      <collision name='collision_prop_4'> 
        <pose>0 0 0 0 -0 0</pose>  
        <geometry>
          <cylinder>
            <length>0.01</length>
            <radius>0.128</radius>
          </cylinder>
        </geometry>
        <surface>
          <contact>
            <ode/>
          </contact>
          <friction>
            <ode/>
          </friction>
        </surface>
      </collision>   
      <visual name='visual_prop_4'> 
        <pose>0 0 0 0 -0 0</pose>
        <geometry>
          <mesh>
            <uri>model://s500/meshes/10in_prop.STL</uri>
            <scale>0.001 0.001 0.001</scale>
          </mesh>
        </geometry>
        <material>
          <script>
            <name>Gazebo/DarkGrey</name>
            <uri>__default__</uri>
          </script>
        </material>
      </visual>
      <gravity>1</gravity> 
      <velocity_decay/>
      <self_collide>0</self_collide>      
    </link>



    <!--Joints-->
    <joint name="livox_joint" type="fixed">
      <parent>drone_frame</parent>
      <child>livox_lipo_ass</child>
      <pose frame=''>0 0 0 0 -0 0</pose>
    </joint>


    <joint name='frame_prop_1' type='revolute'>
      <parent>drone_frame</parent>
      <child>prop_1</child>
      <axis>
        <xyz>0 0 1</xyz>
        <limit>
          <lower>-1e+16</lower>
          <upper>1e+16</upper>
        </limit>
        <dynamics>
          <spring_reference>0</spring_reference>
          <spring_stiffness>0</spring_stiffness>
        </dynamics>
        <use_parent_model_frame>1</use_parent_model_frame>
      </axis>
    </joint>


    <joint name='frame_prop_2' type='revolute'>
      <parent>drone_frame</parent>
      <child>prop_2</child>
      <axis>
        <xyz>0 0 1</xyz>
        <limit>
          <lower>-1e+16</lower>
          <upper>1e+16</upper>
        </limit>
        <dynamics>
          <spring_reference>0</spring_reference>
          <spring_stiffness>0</spring_stiffness>
        </dynamics>
        <use_parent_model_frame>1</use_parent_model_frame>
      </axis>
    </joint>


    <joint name='frame_prop_3' type='revolute'>
      <parent>drone_frame</parent>
      <child>prop_3</child>
      <axis>
        <xyz>0 0 1</xyz>
        <limit>
          <lower>-1e+16</lower>
          <upper>1e+16</upper>
        </limit>
        <dynamics>
          <spring_reference>0</spring_reference>
          <spring_stiffness>0</spring_stiffness>
        </dynamics>
        <use_parent_model_frame>1</use_parent_model_frame>
      </axis>
    </joint>


    <joint name='frame_prop_4' type='revolute'>
      <parent>drone_frame</parent>
      <child>prop_4</child>
      <axis>
        <xyz>0 0 1</xyz>
        <limit>
          <lower>-1e+16</lower>
          <upper>1e+16</upper>
        </limit>
        <dynamics>
          <spring_reference>0</spring_reference>
          <spring_stiffness>0</spring_stiffness>
        </dynamics>
        <use_parent_model_frame>1</use_parent_model_frame>
      </axis>
    </joint>



    <!--Sensors & Joints-->
    <link name='imu_link'>
      <pose>0 0 0.22875 0 -0 0</pose>
      <inertial>
        <mass>0.001</mass>
        <inertia>
          <ixx>0.00001012</ixx>
          <ixy>0</ixy>
          <ixz>0</ixz>
          <iyy>0.00001385</iyy>
          <iyz>0</iyz>
          <izz>0.00000522</izz>
        </inertia>
        <pose>0 0 0 0 -0 0</pose>
      </inertial>
      <visual name='visual_pixhawk4'>
        <pose>0 0 0 0 -0 0</pose>
        <geometry>
          <box>
            <size>0.055 0.038 0.0155</size>          
          </box>
        </geometry>
        <material>
          <script>
            <name>Gazebo/Grey</name>
            <uri>__default__</uri>
          </script>
        </material>
      </visual>
      <sensor name="imu_sensor" type="imu">
        <pose>0 0 0 3.141593 0 0</pose>
        <always_on>1</always_on>
        <update_rate>100000.0</update_rate>
      </sensor>
    </link>
    <joint name='imu_joint' type='revolute'>
      <child>imu_link</child>
      <parent>drone_frame</parent>
      <axis>
        <xyz>1 0 0</xyz>
        <limit>
          <lower>0</lower>
          <upper>0</upper>
          <effort>0</effort>
          <velocity>0</velocity>
        </limit>
        <dynamics>
          <spring_reference>0</spring_reference>
          <spring_stiffness>0</spring_stiffness>
        </dynamics>
        <use_parent_model_frame>1</use_parent_model_frame>
      </axis>
    </joint>


    <link name='camera_link'>
      <pose>0.047 0 0.226 0 -0 0</pose>
      <inertial>
        <mass>0.001</mass>
        <inertia>
          <ixx>1e-05</ixx>
          <ixy>0</ixy>
          <ixz>0</ixz>
          <iyy>1e-05</iyy>
          <iyz>0</iyz>
          <izz>1e-05</izz>
        </inertia>
        <pose>0 0 0 0 -0 0</pose>
      </inertial>
      <visual name="visual_camera">
        <geometry>
          <box>
            <size>0.01 0.01 0.01</size>
          </box>
        </geometry>
      </visual>
      <collision name="collision_camera">
        <geometry>
          <box>
            <size>0.01 0.01 0.01</size>
          </box>
        </geometry>
      </collision>
      <sensor name="camera_sensor" type="camera">
        <horizontal_fov>1.047</horizontal_fov>
        <image>
          <width>320</width>
          <height>240</height>
        </image>
        <clip>
          <near>0.1</near>
          <far>100</far>
        </clip>
        <always_on>1</always_on>
        <update_rate>100.0</update_rate>
        <visualize>false</visualize>
        <pose>0 0 0 0 0 0</pose>
      </sensor>
    </link>
    <joint name="camera_joint" type="fixed">
      <parent>drone_frame</parent>
      <child>camera_link</child>
      <pose frame=''>0 0 0 0 -0 0</pose>
    </joint>


    <include>
      <uri>model://gps</uri>
      <pose>-0.0375 0 0.222 0 0 0</pose>
      <name>gps</name>
    </include>
    <joint name='gps_joint' type='fixed'>
      <child>gps::link</child>
      <parent>drone_frame</parent>
    </joint>



    <!--PX4 Plugins-->
    <plugin name='rosbag' filename='libgazebo_multirotor_base_plugin.so'>
      <robotNamespace/>
      <linkName>drone_frame</linkName>
      <rotorVelocitySlowdownSim>10</rotorVelocitySlowdownSim>
    </plugin>
    <plugin name='front_right_motor_model' filename='libgazebo_motor_model.so'>
      <robotNamespace></robotNamespace>
      <jointName>frame_prop_1</jointName>
      <linkName>prop_1</linkName>
      <turningDirection>ccw</turningDirection>
      <timeConstantUp>0.0125</timeConstantUp>
      <timeConstantDown>0.025</timeConstantDown>
      <maxRotVelocity>1500</maxRotVelocity>
      <motorConstant>8.54858e-06</motorConstant>
      <momentConstant>0.06</momentConstant>
      <commandSubTopic>/gazebo/command/motor_speed</commandSubTopic>
      <motorNumber>0</motorNumber>
      <rotorDragCoefficient>0.000806428</rotorDragCoefficient>
      <rollingMomentCoefficient>1e-06</rollingMomentCoefficient>
      <motorSpeedPubTopic>/motor_speed/0</motorSpeedPubTopic>
      <rotorVelocitySlowdownSim>10</rotorVelocitySlowdownSim>
    </plugin>
    <plugin name='back_left_motor_model' filename='libgazebo_motor_model.so'>
      <robotNamespace></robotNamespace>
      <jointName>frame_prop_2</jointName>
      <linkName>prop_2</linkName>
      <turningDirection>ccw</turningDirection>
      <timeConstantUp>0.0125</timeConstantUp>
      <timeConstantDown>0.025</timeConstantDown>
      <maxRotVelocity>1500</maxRotVelocity>
      <motorConstant>8.54858e-06</motorConstant>
      <momentConstant>0.06</momentConstant>
      <commandSubTopic>/gazebo/command/motor_speed</commandSubTopic>
      <motorNumber>1</motorNumber>
      <rotorDragCoefficient>0.000806428</rotorDragCoefficient>
      <rollingMomentCoefficient>1e-06</rollingMomentCoefficient>
      <motorSpeedPubTopic>/motor_speed/1</motorSpeedPubTopic>
      <rotorVelocitySlowdownSim>10</rotorVelocitySlowdownSim>
    </plugin>
    <plugin name='front_left_motor_model' filename='libgazebo_motor_model.so'>
      <robotNamespace></robotNamespace>
      <jointName>frame_prop_3</jointName>
      <linkName>prop_3</linkName>
      <turningDirection>cw</turningDirection>
      <timeConstantUp>0.0125</timeConstantUp>
      <timeConstantDown>0.025</timeConstantDown>
      <maxRotVelocity>1500</maxRotVelocity>
      <motorConstant>8.54858e-06</motorConstant>
      <momentConstant>0.06</momentConstant>
      <commandSubTopic>/gazebo/command/motor_speed</commandSubTopic>
      <motorNumber>2</motorNumber>
      <rotorDragCoefficient>0.000806428</rotorDragCoefficient>
      <rollingMomentCoefficient>1e-06</rollingMomentCoefficient>
      <motorSpeedPubTopic>/motor_speed/2</motorSpeedPubTopic>
      <rotorVelocitySlowdownSim>10</rotorVelocitySlowdownSim>
    </plugin>
    <plugin name='back_right_motor_model' filename='libgazebo_motor_model.so'>
      <robotNamespace></robotNamespace>
      <jointName>frame_prop_4</jointName>
      <linkName>prop_4</linkName>
      <turningDirection>cw</turningDirection>
      <timeConstantUp>0.0125</timeConstantUp>
      <timeConstantDown>0.025</timeConstantDown>
      <maxRotVelocity>1500</maxRotVelocity>
      <motorConstant>8.54858e-06</motorConstant>
      <momentConstant>0.06</momentConstant>
      <commandSubTopic>/gazebo/command/motor_speed</commandSubTopic>
      <motorNumber>3</motorNumber>
      <rotorDragCoefficient>0.000806428</rotorDragCoefficient>
      <rollingMomentCoefficient>1e-06</rollingMomentCoefficient>
      <motorSpeedPubTopic>/motor_speed/3</motorSpeedPubTopic>
      <rotorVelocitySlowdownSim>10</rotorVelocitySlowdownSim>
    </plugin>


    <plugin name='groundtruth_plugin' filename='libgazebo_groundtruth_plugin.so'>
      <robotNamespace/>
    </plugin>
    <plugin name='magnetometer_plugin' filename='libgazebo_magnetometer_plugin.so'>
      <robotNamespace/>
      <pubRate>100</pubRate>
      <noiseDensity>0.0004</noiseDensity>
      <randomWalk>6.4e-06</randomWalk>
      <biasCorrelationTime>600</biasCorrelationTime>
      <magTopic>/mag</magTopic>
    </plugin>
    <plugin name='barometer_plugin' filename='libgazebo_barometer_plugin.so'>
      <robotNamespace/>
      <pubRate>50</pubRate>
      <baroTopic>/baro</baroTopic>
      <baroDriftPaPerSec>0</baroDriftPaPerSec>
    </plugin>
    <plugin name='mavlink_interface' filename='libgazebo_mavlink_interface.so'>
      <robotNamespace/>
      <imuSubTopic>/imu</imuSubTopic>
      <gpsSubTopic>/gps</gpsSubTopic>
      <magSubTopic>/mag</magSubTopic>
      <baroSubTopic>/baro</baroSubTopic>
      <mavlink_addr>INADDR_ANY</mavlink_addr>
      <mavlink_udp_port>14560</mavlink_udp_port>
      <serialEnabled>false</serialEnabled>
      <serialDevice>/dev/ttyACM0</serialDevice>
      <baudRate>921600</baudRate>
      <qgc_addr>INADDR_ANY</qgc_addr>
      <qgc_udp_port>14550</qgc_udp_port>
      <hil_mode>false</hil_mode>
      <hil_state_level>false</hil_state_level>
      <enable_lockstep>true</enable_lockstep>
      <use_tcp>true</use_tcp>
      <motorSpeedCommandPubTopic>/gazebo/command/motor_speed</motorSpeedCommandPubTopic>
      <control_channels>
        <channel name='rotor1'>
          <input_index>0</input_index>
          <input_offset>0</input_offset>
          <input_scaling>1000</input_scaling>
          <zero_position_disarmed>0</zero_position_disarmed>
          <zero_position_armed>100</zero_position_armed>
          <joint_control_type>velocity</joint_control_type>
        </channel>
        <channel name='rotor2'>
          <input_index>1</input_index>
          <input_offset>0</input_offset>
          <input_scaling>1000</input_scaling>
          <zero_position_disarmed>0</zero_position_disarmed>
          <zero_position_armed>100</zero_position_armed>
          <joint_control_type>velocity</joint_control_type>
        </channel>
        <channel name='rotor3'>
          <input_index>2</input_index>
          <input_offset>0</input_offset>
          <input_scaling>1000</input_scaling>
          <zero_position_disarmed>0</zero_position_disarmed>
          <zero_position_armed>100</zero_position_armed>
          <joint_control_type>velocity</joint_control_type>
        </channel>
        <channel name='rotor4'>
          <input_index>3</input_index>
          <input_offset>0</input_offset>
          <input_scaling>1000</input_scaling>
          <zero_position_disarmed>0</zero_position_disarmed>
          <zero_position_armed>100</zero_position_armed>
          <joint_control_type>velocity</joint_control_type>
        </channel>
      </control_channels>
    </plugin>
    <static>0</static>
    <plugin name='rotors_gazebo_imu_plugin' filename='libgazebo_imu_plugin.so'>
      <robotNamespace/>
      <linkName>imu_link</linkName>
      <imuTopic>/imu</imuTopic>
      <gyroscopeNoiseDensity>0.00018665</gyroscopeNoiseDensity>
      <gyroscopeRandomWalk>3.8785e-05</gyroscopeRandomWalk>
      <gyroscopeBiasCorrelationTime>1000.0</gyroscopeBiasCorrelationTime>
      <gyroscopeTurnOnBiasSigma>0.0087</gyroscopeTurnOnBiasSigma>
      <accelerometerNoiseDensity>0.00186</accelerometerNoiseDensity>
      <accelerometerRandomWalk>0.006</accelerometerRandomWalk>
      <accelerometerBiasCorrelationTime>300.0</accelerometerBiasCorrelationTime>
      <accelerometerTurnOnBiasSigma>0.196</accelerometerTurnOnBiasSigma>
    </plugin>

  </model>
</sdf>
